Workbook
Name SlicerCache_Table_1_Col_1: #N/A

Sheet Customer_Dim
A1: Customer_ID | B1: Name | C1: Age | D1: Gender | E1: City | F1: State | G1: Country | H1: Loyalty_Level
A2: CUST1464 | B2: David Pierce | C2: 45 | D2: Female | E2: Grayland | F2: Washington | G2: USA | H2: Platinum | I2: =IFS(H2="","",H2="Platinum",1,H2="Bronze",2,H2="Gold",3,H2="Silver",4) -> 1
A3: CUST1486 | B3: Eric Lee | C3: 22 | D3: Female | E3: Lake April | F3: Vermont | G3: USA | H3: Bronze | I3: =IFS(H3="","",H3="Platinum",1,H3="Bronze",2,H3="Gold",3,H3="Silver",4) -> 2
A4: CUST1491 | B4: Kaitlin Brown | C4: 52 | D4: Female | E4: Kellyberg | F4: South Dakota | G4: USA | H4: Gold | I4: =IFS(H4="","",H4="Platinum",1,H4="Bronze",2,H4="Gold",3,H4="Silver",4) -> 3
A5: CUST1499 | B5: Philip Pennington | C5: 27 | D5: Female | E5: East Valerieview | F5: Oregon | G5: USA | H5: Platinum | I5: =IFS(H5="","",H5="Platinum",1,H5="Bronze",2,H5="Gold",3,H5="Silver",4) -> 1
A6: CUST1000 | B6: Sheena Bonilla | C6: 55 | D6: Male | E6: Donaldton | F6: North Carolina | G6: USA | I6: =IFS(H6="","",H6="Platinum",1,H6="Bronze",2,H6="Gold",3,H6="Silver",4)
A7: CUST1001 | B7: Eugene Nelson | C7: 26 | D7: Female | E7: Phillipsmouth | F7: North Dakota | G7: USA | H7: Platinum | I7: =IFS(H7="","",H7="Platinum",1,H7="Bronze",2,H7="Gold",3,H7="Silver",4) -> 1
A8: CUST1002 | B8: Dr. Benjamin Price | C8: 29 | D8: Female | E8: Kylebury | F8: Alabama | G8: USA | H8: Platinum | I8: =IFS(H8="","",H8="Platinum",1,H8="Bronze",2,H8="Gold",3,H8="Silver",4) -> 1
A9: CUST1003 | B9: Jeremy Harris | C9: 59 | D9: Female | E9: Thomastown | F9: Ohio | G9: USA | H9: Bronze | I9: =IFS(H9="","",H9="Platinum",1,H9="Bronze",2,H9="Gold",3,H9="Silver",4) -> 2
A10: CUST1004 | B10: Caroline Collins | C10: 64 | D10: Female | E10: Nicholasshire | F10: California | G10: USA | H10: Silver | I10: =IFS(H10="","",H10="Platinum",1,H10="Bronze",2,H10="Gold",3,H10="Silver",4) -> 4
A11: CUST1005 | B11: Christine Vaughn | C11: 24 | D11: Male | E11: East Amandamouth | F11: Oregon | G11: USA | H11: Bronze | I11: =IFS(H11="","",H11="Platinum",1,H11="Bronze",2,H11="Gold",3,H11="Silver",4) -> 2
A12: CUST1006 | B12: Amber Jackson | C12: 29 | D12: Female | E12: Deborahborough | F12: South Dakota | G12: USA | H12: Platinum | I12: =IFS(H12="","",H12="Platinum",1,H12="Bronze",2,H12="Gold",3,H12="Silver",4) -> 1
A13: CUST1007 | B13: Daniel Boyd | C13: 29 | D13: Female | E13: West Pamelafurt | F13: West Virginia | G13: USA | H13: Bronze | I13: =IFS(H13="","",H13="Platinum",1,H13="Bronze",2,H13="Gold",3,H13="Silver",4) -> 2
A14: CUST1008 | B14: Melissa Howard | C14: 53 | D14: Female | E14: Maynardton | F14: New Hampshire | G14: USA | H14: Gold | I14: =IFS(H14="","",H14="Platinum",1,H14="Bronze",2,H14="Gold",3,H14="Silver",4) -> 3
A15: CUST1009 | B15: Ms. Maria Leach | C15: 64 | D15: Male | E15: Melissashire | F15: Pennsylvania | G15: USA | H15: Platinum | I15: =IFS(H15="","",H15="Platinum",1,H15="Bronze",2,H15="Gold",3,H15="Silver",4) -> 1
A16: CUST1010 | B16: Dominic Page | C16: 53 | D16: Male | E16: Port Michaelburgh | F16: Pennsylvania | G16: USA | H16: Bronze | I16: =IFS(H16="","",H16="Platinum",1,H16="Bronze",2,H16="Gold",3,H16="Silver",4) -> 2
A17: CUST1011 | B17: Brian Lopez | C17: 28 | D17: Female | E17: East Krista | F17: New York | G17: USA | H17: Gold | I17: =IFS(H17="","",H17="Platinum",1,H17="Bronze",2,H17="Gold",3,H17="Silver",4) -> 3
A18: CUST1012 | B18: Kenneth Lambert | C18: 55 | D18: Female | E18: North Kathryn | F18: Kansas | G18: USA | H18: Platinum | I18: =IFS(H18="","",H18="Platinum",1,H18="Bronze",2,H18="Gold",3,H18="Silver",4) -> 1
... A23: CUST1017 | B23: Adam Cruz | C23: 60 | D23: Female | E23: Brandonville | F23: Georgia | G23: USA | H23: Platinum | I23: =IFS(H23="","",H23="Platinum",1,H23="Bronze",2,H23="Gold",3,H23="Silver",4) -> 1
A24: CUST1018 | B24: Rhonda Moss | C24: 43 | D24: Male | E24: South William | F24: Kansas | G24: USA | I24: =IFS(H24="","",H24="Platinum",1,H24="Bronze",2,H24="Gold",3,H24="Silver",4)
A25: CUST1019 | B25: Michael Torres | C25: 46 | D25: Female | E25: Gonzalezfort | F25: New Jersey | G25: USA | H25: Platinum | I25: =IFS(H25="","",H25="Platinum",1,H25="Bronze",2,H25="Gold",3,H25="Silver",4) -> 1
A26: CUST1020 | B26: Bridget Allen | C26: 59 | D26: Male | E26: Lake Shaneburgh | F26: Delaware | G26: USA | H26: Silver | I26: =IFS(H26="","",H26="Platinum",1,H26="Bronze",2,H26="Gold",3,H26="Silver",4) -> 4
A27: CUST1021 | B27: Jeff Martinez | C27: 36 | D27: Female | E27: Smithburgh | F27: Oklahoma | G27: USA | H27: Gold | I27: =IFS(H27="","",H27="Platinum",1,H27="Bronze",2,H27="Gold",3,H27="Silver",4) -> 3
A28: CUST1022 | B28: Paul Fox | C28: 33 | D28: Female | E28: Michaelton | F28: Hawaii | G28: USA | H28: Silver | I28: =IFS(H28="","",H28="Platinum",1,H28="Bronze",2,H28="Gold",3,H28="Silver",4) -> 4
A29: CUST1023 | B29: Jonathan Steele | C29: 52 | D29: Female | E29: Molinabury | F29: Oregon | G29: USA | H29: Silver | I29: =IFS(H29="","",H29="Platinum",1,H29="Bronze",2,H29="Gold",3,H29="Silver",4) -> 4
A30: CUST1024 | B30: Heather Collins | C30: 40 | D30: Male | E30: Rogerschester | F30: Idaho | G30: USA | H30: Platinum | I30: =IFS(H30="","",H30="Platinum",1,H30="Bronze",2,H30="Gold",3,H30="Silver",4) -> 1
A31: CUST1025 | B31: Diana Taylor | C31: 59 | D31: Female | E31: Vasqueztown | F31: California | G31: USA | H31: Bronze | I31: =IFS(H31="","",H31="Platinum",1,H31="Bronze",2,H31="Gold",3,H31="Silver",4) -> 2
A32: CUST1026 | B32: Amber Carlson | C32: 18 | D32: Female | E32: East Michellemouth | F32: Missouri | G32: USA | H32: Gold | I32: =IFS(H32="","",H32="Platinum",1,H32="Bronze",2,H32="Gold",3,H32="Silver",4) -> 3
A33: CUST1027 | B33: Leslie Johnson | C33: 31 | D33: Male | E33: Mollyshire | F33: Utah | G33: USA | I33: =IFS(H33="","",H33="Platinum",1,H33="Bronze",2,H33="Gold",3,H33="Silver",4)
A34: CUST1028 | B34: Joshua Ryan | C34: 27 | D34: Female | E34: New David | F34: New Jersey | G34: USA | H34: Platinum | I34: =IFS(H34="","",H34="Platinum",1,H34="Bronze",2,H34="Gold",3,H34="Silver",4) -> 1
A35: CUST1029 | B35: David Arnold | C35: 54 | D35: Female | E35: East Jennifer | F35: California | G35: USA | H35: Silver | I35: =IFS(H35="","",H35="Platinum",1,H35="Bronze",2,H35="Gold",3,H35="Silver",4) -> 4
A36: CUST1030 | B36: Jessica Acevedo | C36: 64 | D36: Female | E36: Amybury | F36: Pennsylvania | G36: USA | H36: Bronze | I36: =IFS(H36="","",H36="Platinum",1,H36="Bronze",2,H36="Gold",3,H36="Silver",4) -> 2
A37: CUST1031 | B37: Sarah Vance | C37: 41 | D37: Male | E37: Johnsonville | F37: Oregon | G37: USA | H37: Silver | I37: =IFS(H37="","",H37="Platinum",1,H37="Bronze",2,H37="Gold",3,H37="Silver",4) -> 4
A38: CUST1032 | B38: Mike Jennings | C38: 48 | D38: Female | E38: Fostermouth | F38: Arizona | G38: USA | H38: Gold | I38: =IFS(H38="","",H38="Platinum",1,H38="Bronze",2,H38="Gold",3,H38="Silver",4) -> 3
A39: CUST1033 | B39: Robert Jones Dds | C39: 25 | D39: Male | E39: Tristanton | F39: Oklahoma | G39: USA | H39: Platinum | I39: =IFS(H39="","",H39="Platinum",1,H39="Bronze",2,H39="Gold",3,H39="Silver",4) -> 1
A40: CUST1034 | B40: Christopher Olson | C40: 27 | D40: Female | E40: West Richard | F40: Maryland | G40: USA | H40: Platinum | I40: =IFS(H40="","",H40="Platinum",1,H40="Bronze",2,H40="Gold",3,H40="Silver",4) -> 1
A41: CUST1035 | B41: Rachel Myers | C41: 52 | D41: Male | E41: Robertberg | F41: North Dakota | G41: USA | H41: Silver | I41: =IFS(H41="","",H41="Platinum",1,H41="Bronze",2,H41="Gold",3,H41="Silver",4) -> 4
A42: CUST1036 | B42: Thomas Phillips | C42: 20 | D42: Female | E42: Luisfurt | F42: Georgia | G42: USA | H42: Gold | I42: =IFS(H42="","",H42="Platinum",1,H42="Bronze",2,H42="Gold",3,H42="Silver",4) -> 3
A43: CUST1037 | B43: Christopher Carter | C43: 27 | D43: Female | E43: Brendastad | F43: South Dakota | G43: USA | I43: =IFS(H43="","",H43="Platinum",1,H43="Bronze",2,H43="Gold",3,H43="Silver",4)
A44: CUST1038 | B44: Deanna Simpson | C44: 35 | D44: Female | E44: Brownport | F44: North Dakota | G44: USA | H44: Bronze | I44: =IFS(H44="","",H44="Platinum",1,H44="Bronze",2,H44="Gold",3,H44="Silver",4) -> 2
...

Sheet Product_Dim
A1: Product_ID | B1: Product_Name | C1: Category | D1: Sub_Category | E1: Brand | F1: Cost | G1: Stock
A2: PROD0 | B2: Brother Laser Printer | C2: Electronics | D2: Computer | E2: Hunt Inc | F2: 112.42 | G2: 416
A3: PROD1 | B3: Men's Graphic T-Shirt | C3: Clothing | D3: Tops | E3: Terry-Moore | F3: 342.56 | G3: 181
A4: PROD2 | B4: Women's Casual Hoodie | C4: Clothing | D4: Outerwear | E4: Sims Inc | G4: 352
A5: PROD3 | B5: Men's Running Jacket | C5: Clothing | D5: Outerwear | E5: Pineda Ltd | F5: 364.67 | G5: 452
A6: PROD4 | B6: Women's Yoga Pants | C6: Clothing | D6: Bottoms | E6: Gonzales-Davis | F6: 306.46 | G6: 487
A7: PROD5 | B7: Men's Leather Belt | C7: Clothing | D7: Accessories | E7: Baldwin, Garza and Gonzalez | F7: 261 | G7: 59
A8: PROD6 | B8: Herbal Face Moisturizer | C8: Beauty | D8: Skincare | E8: Davidson PLC | F8: 312.8 | G8: 350
A9: PROD7 | B9: LED Table Lamp | C9: Home | D9: Lighting | E9: Harrell LLC | F9: 218.86 | G9: 170
A10: PROD8 | B10: Wireless Bluetooth Earbuds | C10: Electronics | D10: Audio | E10: Perez-Johnston | F10: 439.07 | G10: 142
A11: PROD9 | B11: Adjustable Dumbbell Set | C11: Sports | D11: Fitness | E11: Hill PLC | F11: 495.72 | G11: 323
A12: PROD10 | B12: Ceramic Kitchen Bowl Set | C12: Home | D12: Kitchen | E12: Hamilton Group | F12: 298.86 | G12: 308
A13: PROD11 | B13: HD Smart TV Stick | C13: Electronics | D13: Accessories | E13: Gibson, Hobbs and Weaver | F13: 449.4
A14: PROD12 | B14: Hair Strengthening Shampoo | C14: Beauty | D14: Haircare | E14: Rice LLC | F14: 115.82 | G14: 460
A15: PROD13 | B15: USB-C Fast Charger | C15: Electronics | D15: Accessories | E15: Dawson-Perkins | F15: 242.23 | G15: 453
A16: PROD14 | B16: Decorative Wall Mirror | C16: Home | D16: Decor | E16: Luna, Anderson and Bowman | F16: 48.01 | G16: 439
A17: PROD15 | B17: 4K Home Projector | C17: Electronics | D17: Appliances | E17: Thomas LLC | F17: 465.34 | G17: 301
A18: PROD16 | B18: Beard Grooming Kit | C18: Beauty | D18: Grooming | E18: Erickson-Green | F18: 337.42 | G18: 256
A19: PROD17 | B19: Soccer Training Cone Set | C19: Sports | D19: Accessories | E19: Ford, Murphy and Wilson | F19: 144.53 | G19: 367
A20: PROD18 | B20: Women's Denim Jeans | C20: Clothing | D20: Bottoms | E20: Guerra-Hendrix | G20: 343
A21: PROD19 | B21: Knee Support Brace | C21: Sports | D21: Equipment | E21: May-Reese | F21: 21.34 | G21: 65
A22: PROD20 | B22: Outdoor Sports Water Bottle | C22: Sports | D22: Accessories | E22: Soto-Ellis | F22: 131.51
A23: PROD21 | B23: Multi-Purpose Storage Box | C23: Home | D23: Storage | E23: Gardner-Montes | F23: 123.46 | G23: 76
A24: PROD22 | B24: Carbon Fiber Tennis Racket | C24: Sports | D24: Equipment | E24: Flores, Pineda and Rodriguez | F24: 484.62 | G24: 432
A25: PROD23 | B25: Men's Formal Shirt | C25: Clothing | D25: Tops | E25: Moon, Mora and Santos | G25: 360
A26: PROD24 | B26: Foldable Camping Chair | C26: Sports | D26: Outdoor | E26: Cook Ltd | F26: 166.06 | G26: 340
A27: PROD25 | B27: Women's Scarf Set | C27: Clothing | D27: Accessories | E27: Brown and Sons | F27: 174.02 | G27: 268
A28: PROD26 | B28: Wireless Bluetooth Speaker | C28: Electronics | D28: Audio | E28: Reed-Schmidt | F28: 322.41 | G28: 213
A29: PROD27 | B29: Decorative Floor Vase | C29: Home | D29: Decor | E29: Khan, Jones and Paul | G29: 378
A30: PROD28 | B30: Sports Stopwatch Timer | C30: Sports | D30: Accessories | E30: Burns-Hansen | F30: 38.76 | G30: 137
A31: PROD29 | B31: Fabric Sofa Throw Blanket | C31: Home | D31: Decor | E31: Hoffman Group | F31: 218.48 | G31: 276
A32: PROD30 | B32: Stainless Steel Cutlery Set | C32: Home | D32: Kitchen | E32: Stevens, Fernandez and Martin | F32: 19.52 | G32: 57
A33: PROD31 | B33: Basketball | C33: Sports | D33: Team Sports | E33: Nolan-Snow | F33: 204.39 | G33: 281
A34: PROD32 | B34: Vitamin C Face Serum | C34: Beauty | D34: Skincare | E34: Griffin Ltd | F34: 283.83 | G34: 244
A35: PROD33 | B35: Modern Wall Clock | C35: Home | D35: Decor | E35: Weiss-Watson | F35: 179.77 | G35: 305
A36: PROD34 | B36: Gaming Mechanical Keyboard | C36: Electronics | D36: Computer | E36: Lucero LLC | F36: 419.28 | G36: 86
A37: PROD35 | B37: Bedroom Table Lamp | C37: Home | D37: Lighting | E37: Jones LLC | F37: 382.22 | G37: 329
A38: PROD36 | B38: Women's Summer Dress | C38: Clothing | D38: Tops | E38: Smith-Mills | F38: 223.43 | G38: 154
A39: PROD37 | B39: Men's Casual Sneakers | C39: Clothing | D39: Footwear | E39: Hogan-Lee | F39: 353.47 | G39: 214
A40: PROD38 | B40: Sports Water Hydration Pack | C40: Sports | D40: Outdoor | E40: Sims-Smith | F40: 135.61 | G40: 394
...

Sheet Store_Dim
A1: Store_ID | B1: Store_Name | C1: Region | D1: City | E1: Store_Type
A2: STORE0 | B2: Rivera-Warner | C2: East | D2: Washingtonfurt | E2: Flagship
A3: STORE1 | B3: Martinez, Adkins and Johnson | C3: North | D3: Danielmouth | E3: Flagship
A4: STORE2 | B4: Black-Horn | C4: South | D4: North Nancyview | E4: Outlet
A5: STORE3 | B5: Johnson-Wright | C5: North | D5: Hoodberg | E5: Outlet
A6: STORE4 | B6: Alexander Group | C6: South | D6: Port Sharon | E6: Online
A7: STORE5 | B7: Gray Ltd | C7: North | D7: New Michaelchester | E7: Outlet
A8: STORE6 | B8: Benson-Elliott | C8: East | D8: Port Josephberg | E8: Online
A9: STORE7 | B9: Martinez-Mullins | C9: South | D9: Williamsfurt | E9: Online
A10: STORE8 | B10: Bean, Jones and Park | C10: West | D10: Thompsonborough | E10: Online
A11: STORE9 | B11: Moore, Padilla and Butler | C11: South | D11: East Johnstad | E11: Flagship
A12: STORE10 | B12: Hill, Wagner and Ballard | C12: East | D12: East Davidville | E12: Online
... A21: STORE19 | B21: Mann-Austin | C21: East | D21: Vasquezborough | E21: Online

Sheet Sales_Fact
A1: Sales_ID | B1: Order_Date | C1: Customer_ID | D1: Product_ID | E1: Store_ID | F1: Quantity | G1: Unit_Price | H1: Discount | I1: Payment_Type | J1: Total_Amount
A2: SALE0 | B2: 45480 | C2: CUST1409 | D2: PROD97 | E2: STORE3 | F2: 1 | G2: 218.04 | H2: 0.09 | I2: Credit Card | J2: 198.4164
A3: SALE1 | B3: 45285 | C3: CUST1467 | D3: PROD74 | E3: STORE17 | F3: 3 | G3: 104.47 | H3: 0.27 | I3: PayPal | J3: 228.7893
A4: SALE2 | B4: 45446 | C4: CUST1056 | D4: PROD49 | E4: STORE8 | F4: 4 | G4: 914.05 | H4: 0.25 | I4: Credit Card | J4: 2742.15
A5: SALE3 | B5: 45259 | C5: CUST1346 | D5: PROD76 | E5: STORE8 | F5: 1 | G5: 921.51 | H5: 0.16 | I5: COD | J5: 774.0684
A6: SALE4 | B6: 45297 | C6: CUST1493 | D6: PROD59 | E6: STORE5 | F6: 3 | G6: 745.3 | H6: 0.18 | I6: Credit Card | J6: 1833.438
A7: SALE5 | B7: 45499 | C7: CUST1116 | D7: PROD15 | E7: STORE7 | F7: 3 | G7: 147.01 | H7: 0.19 | I7: COD | J7: 357.2343
A8: SALE6 | B8: 45850 | C8: CUST1016 | D8: PROD56 | E8: STORE4 | F8: 2 | G8: 785.31 | H8: 0.15 | I8: PayPal | J8: 1335.027
A9: SALE7 | B9: 45248 | C9: CUST1152 | D9: PROD70 | E9: STORE8 | F9: 4 | G9: 342.39 | H9: 0.23 | I9: PayPal | J9: 1054.5612
A10: SALE8 | B10: 45781 | C10: CUST1187 | D10: PROD99 | E10: STORE5 | G10: 448.25 | H10: 0.07 | I10: PayPal | J10: 1250.6175
A11: SALE9 | B11: 45869 | C11: CUST1464 | D11: PROD33 | E11: STORE0 | F11: 2 | G11: 873.17 | H11: 0.23 | I11: PayPal | J11: 1344.6818
A12: SALE10 | B12: 45335 | C12: CUST1065 | D12: PROD24 | E12: STORE14 | F12: 1 | G12: 278.63 | H12: 0.07 | I12: Credit Card | J12: 259.1259
A13: SALE11 | B13: 45801 | C13: CUST1320 | D13: PROD39 | E13: STORE1 | F13: 4 | G13: 286.92 | H13: 0.17 | I13: Credit Card | J13: 952.5744
A14: SALE12 | B14: 45528 | C14: CUST1237 | D14: PROD88 | E14: STORE4 | F14: 4 | G14: 644.58 | H14: 0.01 | I14: Credit Card | J14: 2552.5368
A15: SALE13 | B15: 45875 | C15: CUST1443 | D15: PROD34 | E15: STORE16 | F15: 2 | G15: 316.9 | H15: 0.3 | I15: PayPal | J15: 443.66
A16: SALE14 | B16: 45829 | C16: CUST1348 | D16: PROD24 | E16: STORE15 | F16: 4 | G16: 403.47 | H16: 0.29 | I16: PayPal | J16: 1145.8548
A17: SALE15 | B17: 45636 | C17: CUST1435 | D17: PROD36 | E17: STORE9 | G17: 871.34 | H17: 0.04 | I17: COD | J17: 2509.4592
A18: SALE16 | B18: 45913 | C18: CUST1276 | D18: PROD65 | E18: STORE19 | F18: 2 | G18: 451.98 | H18: 0.25 | I18: Credit Card | J18: 677.97
A19: SALE17 | B19: 45637 | C19: CUST1079 | D19: PROD27 | E19: STORE4 | F19: 2 | G19: 502.69 | H19: 0.23 | I19: Credit Card | J19: 774.1426
A20: SALE18 | B20: 45517 | C20: CUST1094 | D20: PROD39 | E20: STORE4 | F20: 2 | G20: 559.23 | H20: 0.25 | I20: COD | J20: 838.845
A21: SALE19 | B21: 45369 | C21: CUST1239 | D21: PROD60 | E21: STORE13 | F21: 4 | H21: 0.04 | I21: COD | J21: 1782.4512
A22: SALE20 | B22: 45843 | C22: CUST1144 | D22: PROD72 | E22: STORE17 | F22: 3 | G22: 986.04 | H22: 0.27 | I22: COD | J22: 2159.4276
A23: SALE21 | B23: 45447 | C23: CUST1396 | D23: PROD43 | E23: STORE18 | F23: 1 | G23: 589.56 | H23: 0.22 | I23: Credit Card | J23: 459.8568
A24: SALE22 | B24: 45394 | C24: CUST1476 | D24: PROD69 | E24: STORE10 | F24: 3 | G24: 979.42 | H24: 0.03 | I24: PayPal | J24: 2850.1122
A25: SALE23 | B25: 45466 | C25: CUST1368 | D25: PROD12 | E25: STORE8 | F25: 1 | G25: 719.28 | H25: 0.08 | I25: Credit Card | J25: 661.7376
A26: SALE24 | B26: 45908 | C26: CUST1186 | D26: PROD67 | E26: STORE6 | F26: 3 | G26: 77.6 | H26: 0.07 | I26: Credit Card | J26: 216.504
A27: SALE25 | B27: 45552 | C27: CUST1381 | D27: PROD5 | E27: STORE3 | F27: 4 | G27: 852.71 | H27: 0.14 | I27: PayPal | J27: 2933.3224
A28: SALE26 | B28: 45294 | C28: CUST1213 | D28: PROD98 | E28: STORE8 | F28: 4 | G28: 156.16 | I28: Credit Card | J28: 599.6544
A29: SALE27 | B29: 45710 | C29: CUST1200 | D29: PROD77 | E29: STORE8 | F29: 3 | G29: 815.49 | H29: 0.17 | I29: Credit Card | J29: 2030.5701
A30: SALE28 | B30: 45923 | C30: CUST1148 | D30: PROD13 | E30: STORE2 | F30: 2 | G30: 74.21 | H30: 0.11 | I30: PayPal | J30: 132.0938
A31: SALE29 | B31: 45302 | C31: CUST1348 | D31: PROD99 | E31: STORE3 | G31: 451.67 | H31: 0.15 | I31: Credit Card | J31: 1535.678
A32: SALE30 | B32: 45217 | C32: CUST1028 | D32: PROD5 | E32: STORE19 | F32: 1 | G32: 429.38 | H32: 0.13 | I32: PayPal | J32: 373.5606
A33: SALE31 | B33: 45593 | C33: CUST1412 | D33: PROD53 | E33: STORE12 | F33: 2 | G33: 148.96 | H33: 0.03 | I33: COD | J33: 288.9824
A34: SALE32 | B34: 45597 | C34: CUST1398 | D34: PROD75 | E34: STORE8 | F34: 4 | G34: 313.83 | H34: 0.08 | I34: Credit Card | J34: 1154.8944
A35: SALE33 | B35: 45620 | C35: CUST1453 | D35: PROD12 | E35: STORE6 | F35: 2 | G35: 717.31 | H35: 0.15 | I35: Credit Card | J35: 1219.427
A36: SALE34 | B36: 45215 | C36: CUST1344 | D36: PROD79 | E36: STORE1 | G36: 873.22 | H36: 0.18 | I36: Credit Card | J36: 2148.1212
A37: SALE35 | B37: 45878 | C37: CUST1218 | D37: PROD16 | E37: STORE3 | F37: 4 | G37: 109.36 | H37: 0.19 | I37: COD | J37: 354.3264
A38: SALE36 | B38: 45635 | C38: CUST1086 | D38: PROD5 | E38: STORE7 | F38: 3 | G38: 559.52 | H38: 0.16 | I38: PayPal | J38: 1409.9904
A39: SALE37 | B39: 45329 | C39: CUST1492 | D39: PROD10 | E39: STORE17 | F39: 3 | G39: 121.76 | H39: 0.27 | I39: PayPal | J39: 266.6544
A40: SALE38 | B40: 45378 | C40: CUST1189 | D40: PROD33 | E40: STORE13 | F40: 4 | G40: 735.32 | H40: 0.06 | I40: COD | J40: 2764.8032
...

Sheet Sales Analysis Table 1
A1: Sales_ID | B1: Order_Date | C1: Month | D1: Year | E1: Customer_ID | F1: Customer_Age | G1: Age Range | H1: Gender | I1: Loyalty_Level | J1: City | K1: State | L1: Region | M1: Product_ID | N1: Product_Category | O1: Product_SubCategory | P1: Brand | Q1: Store_ID | R1: Store_Name | S1: Store_Type | T1: Quantity | U1: Unit_Price | V1: Discount | W1: Stock | X1: Payment_Type | Y1: Total_Amount | Z1: Product
A2: SALE0 | B2: 45480 | C2: July | D2: =YEAR(B2) -> 2024 | E2: CUST1409 | F2: 55 | G2: =IF(F2<18,"Under 18", IF(F2<=25,"18-25", IF(F2<=35,"26-35", IF(F2<=45,"36-45", IF(F2<=55,"46-55", IF(F2<=65,"56-65","65+")))))) -> 46-55 | H2: {=XLOOKUP(E2,Customer_Dim!A:A,Customer_Dim!D:D)} -> Male | I2: {=XLOOKUP(E2,Customer_Dim!A:A,Customer_Dim!H:H)} -> Gold | J2: {=XLOOKUP(E2,Customer_Dim!A:A,Customer_Dim!E:E)} -> Kathleenport | K2: {=XLOOKUP(E2,Customer_Dim!A:A,Customer_Dim!F:F)} -> Wyoming | L2: {=XLOOKUP(Q2,Store_Dim!A:A,Store_Dim!C:C)} -> North | M2: PROD97 | N2: {=XLOOKUP(M2,Product_Dim!A:A,Product_Dim!C:C)} -> Sports | O2: {=XLOOKUP(M2,Product_Dim!A:A,Product_Dim!D:D)} -> Team Sports | P2: Khan LLC | Q2: STORE3 | R2: {=XLOOKUP(Q2,Store_Dim!A:A,Store_Dim!B:B)} -> Johnson-Wright | S2: {=XLOOKUP(Q2,Store_Dim!A:A,Store_Dim!E:E)} -> Outlet | T2: 1 | U2: 218.04 | V2: 0.09 | W2: 471 | X2: Credit Card | Y2: 198.4164 | Z2: {=XLOOKUP(M2,Product_Dim!A:A,Product_Dim!B:B)} -> Cricket Bat
A3: SALE1 | B3: 45285 | C3: December | D3: =YEAR(B3) -> 2023 | E3: CUST1467 | F3: 63 | G3: =IF(F3<18,"Under 18", IF(F3<=25,"18-25", IF(F3<=35,"26-35", IF(F3<=45,"36-45", IF(F3<=55,"46-55", IF(F3<=65,"56-65","65+")))))) -> 56-65 | H3: {=XLOOKUP(E3,Customer_Dim!A:A,Customer_Dim!D:D)} -> Female | I3: {=XLOOKUP(E3,Customer_Dim!A:A,Customer_Dim!H:H)} -> Gold | J3: {=XLOOKUP(E3,Customer_Dim!A:A,Customer_Dim!E:E)} -> Oneillfurt | K3: {=XLOOKUP(E3,Customer_Dim!A:A,Customer_Dim!F:F)} -> Vermont | L3: {=XLOOKUP(Q3,Store_Dim!A:A,Store_Dim!C:C)} -> North | M3: PROD74 | N3: {=XLOOKUP(M3,Product_Dim!A:A,Product_Dim!C:C)} -> Electronics | O3: {=XLOOKUP(M3,Product_Dim!A:A,Product_Dim!D:D)} -> Audio | P3: Bruce-Bowen | Q3: STORE17 | R3: {=XLOOKUP(Q3,Store_Dim!A:A,Store_Dim!B:B)} -> Holloway Ltd | S3: {=XLOOKUP(Q3,Store_Dim!A:A,Store_Dim!E:E)} -> Flagship | T3: 3 | U3: 104.47 | V3: 0.27 | W3: 159 | X3: PayPal | Y3: 228.7893 | Z3: {=XLOOKUP(M3,Product_Dim!A:A,Product_Dim!B:B)} -> Bluetooth Car Audio System
A4: SALE2 | B4: 45446 | C4: June | D4: =YEAR(B4) -> 2024 | E4: CUST1056 | F4: 49 | G4: =IF(F4<18,"Under 18", IF(F4<=25,"18-25", IF(F4<=35,"26-35", IF(F4<=45,"36-45", IF(F4<=55,"46-55", IF(F4<=65,"56-65","65+")))))) -> 46-55 | H4: {=XLOOKUP(E4,Customer_Dim!A:A,Customer_Dim!D:D)} -> Female | I4: {=XLOOKUP(E4,Customer_Dim!A:A,Customer_Dim!H:H)} -> Gold | J4: {=XLOOKUP(E4,Customer_Dim!A:A,Customer_Dim!E:E)} -> Deborahberg | K4: {=XLOOKUP(E4,Customer_Dim!A:A,Customer_Dim!F:F)} -> Pennsylvania | L4: {=XLOOKUP(Q4,Store_Dim!A:A,Store_Dim!C:C)} -> West | M4: PROD49 | N4: {=XLOOKUP(M4,Product_Dim!A:A,Product_Dim!C:C)} -> Beauty | O4: {=XLOOKUP(M4,Product_Dim!A:A,Product_Dim!D:D)} -> Fragrance | P4: Sullivan and Sons | Q4: STORE8 | R4: {=XLOOKUP(Q4,Store_Dim!A:A,Store_Dim!B:B)} -> Bean, Jones and Park | S4: {=XLOOKUP(Q4,Store_Dim!A:A,Store_Dim!E:E)} -> Online | T4: 4 | U4: 914.05 | V4: 0.25 | W4: 267 | X4: Credit Card | Y4: 2742.15 | Z4: {=XLOOKUP(M4,Product_Dim!A:A,Product_Dim!B:B)} -> Men's Roll-On Perfume
A5: SALE3 | B5: 45259 | C5: November | D5: =YEAR(B5) -> 2023 | E5: CUST1346 | F5: 58 | G5: =IF(F5<18,"Under 18", IF(F5<=25,"18-25", IF(F5<=35,"26-35", IF(F5<=45,"36-45", IF(F5<=55,"46-55", IF(F5<=65,"56-65","65+")))))) -> 56-65 | H5: {=XLOOKUP(E5,Customer_Dim!A:A,Customer_Dim!D:D)} -> Female | I5: {=XLOOKUP(E5,Customer_Dim!A:A,Customer_Dim!H:H)} -> Platinum | J5: {=XLOOKUP(E5,Customer_Dim!A:A,Customer_Dim!E:E)} -> Port Crystalberg | K5: {=XLOOKUP(E5,Customer_Dim!A:A,Customer_Dim!F:F)} -> Tennessee | L5: {=XLOOKUP(Q5,Store_Dim!A:A,Store_Dim!C:C)} -> West | M5: PROD76 | N5: {=XLOOKUP(M5,Product_Dim!A:A,Product_Dim!C:C)} -> Electronics | O5: {=XLOOKUP(M5,Product_Dim!A:A,Product_Dim!D:D)} -> Computer | P5: Larson Ltd | Q5: STORE8 | R5: {=XLOOKUP(Q5,Store_Dim!A:A,Store_Dim!B:B)} -> Bean, Jones and Park | S5: {=XLOOKUP(Q5,Store_Dim!A:A,Store_Dim!E:E)} -> Online | T5: 1 | U5: 921.51 | V5: 0.16 | W5: 320 | X5: COD | Y5: 774.0684 | Z5: {=XLOOKUP(M5,Product_Dim!A:A,Product_Dim!B:B)} -> Wireless Mouse
A6: SALE4 | B6: 45297 | C6: January | D6: =YEAR(B6) -> 2024 | E6: CUST1493 | F6: 28 | G6: =IF(F6<18,"Under 18", IF(F6<=25,"18-25", IF(F6<=35,"26-35", IF(F6<=45,"36-45", IF(F6<=55,"46-55", IF(F6<=65,"56-65","65+")))))) -> 26-35 | H6: {=XLOOKUP(E6,Customer_Dim!A:A,Customer_Dim!D:D)} -> Male | I6: {=XLOOKUP(E6,Customer_Dim!A:A,Customer_Dim!H:H)} -> Silver | J6: {=XLOOKUP(E6,Customer_Dim!A:A,Customer_Dim!E:E)} -> South William | K6: {=XLOOKUP(E6,Customer_Dim!A:A,Customer_Dim!F:F)} -> Alabama | L6: {=XLOOKUP(Q6,Store_Dim!A:A,Store_Dim!C:C)} -> North | M6: PROD59 | N6: {=XLOOKUP(M6,Product_Dim!A:A,Product_Dim!C:C)} -> Beauty | O6: {=XLOOKUP(M6,Product_Dim!A:A,Product_Dim!D:D)} -> Haircare | P6: Cline-Mccarthy | Q6: STORE5 | R6: {=XLOOKUP(Q6,Store_Dim!A:A,Store_Dim!B:B)} -> Gray Ltd | S6: {=XLOOKUP(Q6,Store_Dim!A:A,Store_Dim!E:E)} -> Outlet | T6: 3 | U6: 745.3 | V6: 0.18 | W6: 399 | X6: Credit Card | Y6: 1833.438 | Z6: {=XLOOKUP(M6,Product_Dim!A:A,Product_Dim!B:B)} -> Men's Hair Styling Gel
A7: SALE5 | B7: 45499 | C7: July | D7: =YEAR(B7) -> 2024 | E7: CUST1116 | F7: 18 | G7: =IF(F7<18,"Under 18", IF(F7<=25,"18-25", IF(F7<=35,"26-35", IF(F7<=45,"36-45", IF(F7<=55,"46-55", IF(F7<=65,"56-65","65+")))))) -> 18-25 | H7: {=XLOOKUP(E7,Customer_Dim!A:A,Customer_Dim!D:D)} -> Female | I7: {=XLOOKUP(E7,Customer_Dim!A:A,Customer_Dim!H:H)} -> Platinum | J7: {=XLOOKUP(E7,Customer_Dim!A:A,Customer_Dim!E:E)} -> North Davidport | K7: {=XLOOKUP(E7,Customer_Dim!A:A,Customer_Dim!F:F)} -> Rhode Island | L7: {=XLOOKUP(Q7,Store_Dim!A:A,Store_Dim!C:C)} -> South | M7: PROD15 | N7: {=XLOOKUP(M7,Product_Dim!A:A,Product_Dim!C:C)} -> Electronics | O7: {=XLOOKUP(M7,Product_Dim!A:A,Product_Dim!D:D)} -> Appliances | P7: Thomas LLC | Q7: STORE7 | R7: {=XLOOKUP(Q7,Store_Dim!A:A,Store_Dim!B:B)} -> Martinez-Mullins | S7: {=XLOOKUP(Q7,Store_Dim!A:A,Store_Dim!E:E)} -> Online | T7: 3 | U7: 147.01 | V7: 0.19 | W7: 301 | X7: COD | Y7: 357.2343 | Z7: {=XLOOKUP(M7,Product_Dim!A:A,Product_Dim!B:B)} -> 4K Home Projector
A8: SALE6 | B8: 45850 | C8: July | D8: =YEAR(B8) -> 2025 | E8: CUST1016 | F8: 24 | G8: =IF(F8<18,"Under 18", IF(F8<=25,"18-25", IF(F8<=35,"26-35", IF(F8<=45,"36-45", IF(F8<=55,"46-55", IF(F8<=65,"56-65","65+")))))) -> 18-25 | H8: {=XLOOKUP(E8,Customer_Dim!A:A,Customer_Dim!D:D)} -> Female | I8: {=XLOOKUP(E8,Customer_Dim!A:A,Customer_Dim!H:H)} -> Bronze | J8: {=XLOOKUP(E8,Customer_Dim!A:A,Customer_Dim!E:E)} -> South Christopher | K8: {=XLOOKUP(E8,Customer_Dim!A:A,Customer_Dim!F:F)} -> Pennsylvania | L8: {=XLOOKUP(Q8,Store_Dim!A:A,Store_Dim!C:C)} -> South | M8: PROD56 | N8: {=XLOOKUP(M8,Product_Dim!A:A,Product_Dim!C:C)} -> Home | O8: {=XLOOKUP(M8,Product_Dim!A:A,Product_Dim!D:D)} -> Decor | P8: Hernandez, Kennedy and Porter | Q8: STORE4 | R8: {=XLOOKUP(Q8,Store_Dim!A:A,Store_Dim!B:B)} -> Alexander Group | S8: {=XLOOKUP(Q8,Store_Dim!A:A,Store_Dim!E:E)} -> Online | T8: 2 | U8: 785.31 | V8: 0.15 | W8: 190 | X8: PayPal | Y8: 1335.027 | Z8: {=XLOOKUP(M8,Product_Dim!A:A,Product_Dim!B:B)} -> Premium Blanket Throw
A9: SALE7 | B9: 45248 | C9: November | D9: =YEAR(B9) -> 2023 | E9: CUST1152 | F9: 41 | G9: =IF(F9<18,"Under 18", IF(F9<=25,"18-25", IF(F9<=35,"26-35", IF(F9<=45,"36-45", IF(F9<=55,"46-55", IF(F9<=65,"56-65","65+")))))) -> 36-45 | H9: {=XLOOKUP(E9,Customer_Dim!A:A,Customer_Dim!D:D)} -> Female | I9: {=XLOOKUP(E9,Customer_Dim!A:A,Customer_Dim!H:H)} -> Platinum | J9: {=XLOOKUP(E9,Customer_Dim!A:A,Customer_Dim!E:E)} -> Jaredville | K9: {=XLOOKUP(E9,Customer_Dim!A:A,Customer_Dim!F:F)} -> Missouri | L9: {=XLOOKUP(Q9,Store_Dim!A:A,Store_Dim!C:C)} -> West | M9: PROD70 | N9: {=XLOOKUP(M9,Product_Dim!A:A,Product_Dim!C:C)} -> Home | O9: {=XLOOKUP(M9,Product_Dim!A:A,Product_Dim!D:D)} -> Storage | P9: Duran Group | Q9: STORE8 | R9: {=XLOOKUP(Q9,Store_Dim!A:A,Store_Dim!B:B)} -> Bean, Jones and Park | S9: {=XLOOKUP(Q9,Store_Dim!A:A,Store_Dim!E:E)} -> Online | T9: 4 | U9: 342.39 | V9: 0.23 | W9: 89 | X9: PayPal | Y9: 1054.5612 | Z9: {=XLOOKUP(M9,Product_Dim!A:A,Product_Dim!B:B)} -> Kitchen Storage Rack
A10: SALE8 | B10: 45781 | C10: May | D10: =YEAR(B10) -> 2025 | E10: CUST1187 | F10: 60 | G10: =IF(F10<18,"Under 18", IF(F10<=25,"18-25", IF(F10<=35,"26-35", IF(F10<=45,"36-45", IF(F10<=55,"46-55", IF(F10<=65,"56-65","65+")))))) -> 56-65 | H10: {=XLOOKUP(E10,Customer_Dim!A:A,Customer_Dim!D:D)} -> Female | I10: {=XLOOKUP(E10,Customer_Dim!A:A,Customer_Dim!H:H)} -> Platinum | J10: {=XLOOKUP(E10,Customer_Dim!A:A,Customer_Dim!E:E)} -> Lake Blaketon | K10: {=XLOOKUP(E10,Customer_Dim!A:A,Customer_Dim!F:F)} -> Alabama | L10: {=XLOOKUP(Q10,Store_Dim!A:A,Store_Dim!C:C)} -> North | M10: PROD99 | N10: {=XLOOKUP(M10,Product_Dim!A:A,Product_Dim!C:C)} -> Home | O10: {=XLOOKUP(M10,Product_Dim!A:A,Product_Dim!D:D)} -> Kitchen | P10: Campbell Ltd | Q10: STORE5 | R10: {=XLOOKUP(Q10,Store_Dim!A:A,Store_Dim!B:B)} -> Gray Ltd | S10: {=XLOOKUP(Q10,Store_Dim!A:A,Store_Dim!E:E)} -> Outlet | T10: =Y10/(U10*(1-V10)) -> 3 | U10: 448.25 | V10: 0.07 | W10: 146 | X10: PayPal | Y10: 1250.6175 | Z10: {=XLOOKUP(M10,Product_Dim!A:A,Product_Dim!B:B)} -> Stainless Steel Cookware Set
A11: SALE9 | B11: 45869 | C11: July | D11: =YEAR(B11) -> 2025 | E11: CUST1464 | F11: 41.576845 | G11: =IF(F11<18,"Under 18", IF(F11<=25,"18-25", IF(F11<=35,"26-35", IF(F11<=45,"36-45", IF(F11<=55,"46-55", IF(F11<=65,"56-65","65+")))))) -> 36-45 | H11: {=XLOOKUP(E11,Customer_Dim!A:A,Customer_Dim!D:D)} -> Female | I11: {=XLOOKUP(E11,Customer_Dim!A:A,Customer_Dim!H:H)} -> Platinum | J11: {=XLOOKUP(E11,Customer_Dim!A:A,Customer_Dim!E:E)} -> Grayland | K11: {=XLOOKUP(E11,Customer_Dim!A:A,Customer_Dim!F:F)} -> Washington | L11: {=XLOOKUP(Q11,Store_Dim!A:A,Store_Dim!C:C)} -> East | M11: PROD33 | N11: {=XLOOKUP(M11,Product_Dim!A:A,Product_Dim!C:C)} -> Home | O11: {=XLOOKUP(M11,Product_Dim!A:A,Product_Dim!D:D)} -> Decor | P11: Weiss-Watson | Q11: STORE0 | R11: {=XLOOKUP(Q11,Store_Dim!A:A,Store_Dim!B:B)} -> Rivera-Warner | S11: {=XLOOKUP(Q11,Store_Dim!A:A,Store_Dim!E:E)} -> Flagship | T11: 2 | U11: 873.17 | V11: 0.23 | W11: 305 | X11: PayPal | Y11: 1344.6818 | Z11: {=XLOOKUP(M11,Product_Dim!A:A,Product_Dim!B:B)} -> Modern Wall Clock
A12: SALE10 | B12: 45335 | C12: February | D12: =YEAR(B12) -> 2024 | E12: CUST1065 | F12: 21 | G12: =IF(F12<18,"Under 18", IF(F12<=25,"18-25", IF(F12<=35,"26-35", IF(F12<=45,"36-45", IF(F12<=55,"46-55", IF(F12<=65,"56-65","65+")))))) -> 18-25 | H12: {=XLOOKUP(E12,Customer_Dim!A:A,Customer_Dim!D:D)} -> Female | I12: {=XLOOKUP(E12,Customer_Dim!A:A,Customer_Dim!H:H)} -> Silver | J12: {=XLOOKUP(E12,Customer_Dim!A:A,Customer_Dim!E:E)} -> Woodmouth | K12: {=XLOOKUP(E12,Customer_Dim!A:A,Customer_Dim!F:F)} -> Nevada | L12: {=XLOOKUP(Q12,Store_Dim!A:A,Store_Dim!C:C)} -> South | M12: PROD24 | N12: {=XLOOKUP(M12,Product_Dim!A:A,Product_Dim!C:C)} -> Sports | O12: {=XLOOKUP(M12,Product_Dim!A:A,Product_Dim!D:D)} -> Outdoor | P12: Cook Ltd | Q12: STORE14 | R12: {=XLOOKUP(Q12,Store_Dim!A:A,Store_Dim!B:B)} -> Mcdonald Inc | S12: {=XLOOKUP(Q12,Store_Dim!A:A,Store_Dim!E:E)} -> Outlet | T12: 1 | U12: 278.63 | V12: 0.07 | W12: 340 | X12: Credit Card | Y12: 259.1259 | Z12: {=XLOOKUP(M12,Product_Dim!A:A,Product_Dim!B:B)} -> Foldable Camping Chair
A13: SALE11 | B13: 45801 | C13: May | D13: =YEAR(B13) -> 2025 | E13: CUST1320 | F13: 34 | G13: =IF(F13<18,"Under 18", IF(F13<=25,"18-25", IF(F13<=35,"26-35", IF(F13<=45,"36-45", IF(F13<=55,"46-55", IF(F13<=65,"56-65","65+")))))) -> 26-35 | H13: {=XLOOKUP(E13,Customer_Dim!A:A,Customer_Dim!D:D)} -> Female | I13: {=XLOOKUP(E13,Customer_Dim!A:A,Customer_Dim!H:H)} -> Bronze | J13: {=XLOOKUP(E13,Customer_Dim!A:A,Customer_Dim!E:E)} -> South Darrenland | K13: {=XLOOKUP(E13,Customer_Dim!A:A,Customer_Dim!F:F)} -> Iowa | L13: {=XLOOKUP(Q13,Store_Dim!A:A,Store_Dim!C:C)} -> North | M13: PROD39 | N13: {=XLOOKUP(M13,Product_Dim!A:A,Product_Dim!C:C)} -> Electronics | O13: {=XLOOKUP(M13,Product_Dim!A:A,Product_Dim!D:D)} -> Mobile | P13: Cummings and Sons | Q13: STORE1 | R13: {=XLOOKUP(Q13,Store_Dim!A:A,Store_Dim!B:B)} -> Martinez, Adkins and Johnson | S13: {=XLOOKUP(Q13,Store_Dim!A:A,Store_Dim!E:E)} -> Flagship | T13: 4 | U13: 286.92 | V13: 0.17 | W13: 301 | X13: Credit Card | Y13: 952.5744 | Z13: {=XLOOKUP(M13,Product_Dim!A:A,Product_Dim!B:B)} -> Portable Power Bank
A14: SALE12 | B14: 45528 | C14: August | D14: =YEAR(B14) -> 2024 | E14: CUST1237 | F14: 41 | G14: =IF(F14<18,"Under 18", IF(F14<=25,"18-25", IF(F14<=35,"26-35", IF(F14<=45,"36-45", IF(F14<=55,"46-55", IF(F14<=65,"56-65","65+")))))) -> 36-45 | H14: {=XLOOKUP(E14,Customer_Dim!A:A,Customer_Dim!D:D)} -> Female | I14: {=XLOOKUP(E14,Customer_Dim!A:A,Customer_Dim!H:H)} -> Gold | J14: {=XLOOKUP(E14,Customer_Dim!A:A,Customer_Dim!E:E)} -> Susanstad | K14: {=XLOOKUP(E14,Customer_Dim!A:A,Customer_Dim!F:F)} -> Montana | L14: {=XLOOKUP(Q14,Store_Dim!A:A,Store_Dim!C:C)} -> South | M14: PROD88 | N14: {=XLOOKUP(M14,Product_Dim!A:A,Product_Dim!C:C)} -> Sports | O14: {=XLOOKUP(M14,Product_Dim!A:A,Product_Dim!D:D)} -> Accessories | P14: Olsen-Daniels | Q14: STORE4 | R14: {=XLOOKUP(Q14,Store_Dim!A:A,Store_Dim!B:B)} -> Alexander Group | S14: {=XLOOKUP(Q14,Store_Dim!A:A,Store_Dim!E:E)} -> Online | T14: 4 | U14: 644.58 | V14: 0.01 | W14: 232 | X14: Credit Card | Y14: 2552.5368 | Z14: {=XLOOKUP(M14,Product_Dim!A:A,Product_Dim!B:B)} -> Sports Wrist Sweatbands
A15: SALE13 | B15: 45875 | C15: August | D15: =YEAR(B15) -> 2025 | E15: CUST1443 | F15: 51 | G15: =IF(F15<18,"Under 18", IF(F15<=25,"18-25", IF(F15<=35,"26-35", IF(F15<=45,"36-45", IF(F15<=55,"46-55", IF(F15<=65,"56-65","65+")))))) -> 46-55 | H15: {=XLOOKUP(E15,Customer_Dim!A:A,Customer_Dim!D:D)} -> Male | I15: {=XLOOKUP(E15,Customer_Dim!A:A,Customer_Dim!H:H)} -> Silver | J15: {=XLOOKUP(E15,Customer_Dim!A:A,Customer_Dim!E:E)} -> New Donnabury | K15: {=XLOOKUP(E15,Customer_Dim!A:A,Customer_Dim!F:F)} -> Texas | L15: {=XLOOKUP(Q15,Store_Dim!A:A,Store_Dim!C:C)} -> West | M15: PROD34 | N15: {=XLOOKUP(M15,Product_Dim!A:A,Product_Dim!C:C)} -> Electronics | O15: {=XLOOKUP(M15,Product_Dim!A:A,Product_Dim!D:D)} -> Computer | P15: Lucero LLC | Q15: STORE16 | R15: {=XLOOKUP(Q15,Store_Dim!A:A,Store_Dim!B:B)} -> Frederick-Wright | S15: {=XLOOKUP(Q15,Store_Dim!A:A,Store_Dim!E:E)} -> Flagship | T15: 2 | U15: 316.9 | V15: 0.3 | W15: 86 | X15: PayPal | Y15: 443.66 | Z15: {=XLOOKUP(M15,Product_Dim!A:A,Product_Dim!B:B)} -> Gaming Mechanical Keyboard
A16: SALE14 | B16: 45829 | C16: June | D16: =YEAR(B16) -> 2025 | E16: CUST1348 | F16: 55 | G16: =IF(F16<18,"Under 18", IF(F16<=25,"18-25", IF(F16<=35,"26-35", IF(F16<=45,"36-45", IF(F16<=55,"46-55", IF(F16<=65,"56-65","65+")))))) -> 46-55 | H16: {=XLOOKUP(E16,Customer_Dim!A:A,Customer_Dim!D:D)} -> Male | I16: {=XLOOKUP(E16,Customer_Dim!A:A,Customer_Dim!H:H)} -> Silver | J16: {=XLOOKUP(E16,Customer_Dim!A:A,Customer_Dim!E:E)} -> Shannonview | K16: {=XLOOKUP(E16,Customer_Dim!A:A,Customer_Dim!F:F)} -> Pennsylvania | L16: {=XLOOKUP(Q16,Store_Dim!A:A,Store_Dim!C:C)} -> North | M16: PROD24 | N16: {=XLOOKUP(M16,Product_Dim!A:A,Product_Dim!C:C)} -> Sports | O16: {=XLOOKUP(M16,Product_Dim!A:A,Product_Dim!D:D)} -> Outdoor | P16: Cook Ltd | Q16: STORE15 | R16: {=XLOOKUP(Q16,Store_Dim!A:A,Store_Dim!B:B)} -> Shelton PLC | S16: {=XLOOKUP(Q16,Store_Dim!A:A,Store_Dim!E:E)} -> Flagship | T16: 4 | U16: 403.47 | V16: 0.29 | W16: 340 | X16: PayPal | Y16: 1145.8548 | Z16: {=XLOOKUP(M16,Product_Dim!A:A,Product_Dim!B:B)} -> Foldable Camping Chair
A17: SALE15 | B17: 45636 | C17: December | D17: =YEAR(B17) -> 2024 | E17: CUST1435 | F17: 37 | G17: =IF(F17<18,"Under 18", IF(F17<=25,"18-25", IF(F17<=35,"26-35", IF(F17<=45,"36-45", IF(F17<=55,"46-55", IF(F17<=65,"56-65","65+")))))) -> 36-45 | H17: {=XLOOKUP(E17,Customer_Dim!A:A,Customer_Dim!D:D)} -> Female | I17: {=XLOOKUP(E17,Customer_Dim!A:A,Customer_Dim!H:H)} -> Silver | J17: {=XLOOKUP(E17,Customer_Dim!A:A,Customer_Dim!E:E)} -> Wesleyhaven | K17: {=XLOOKUP(E17,Customer_Dim!A:A,Customer_Dim!F:F)} -> Idaho | L17: {=XLOOKUP(Q17,Store_Dim!A:A,Store_Dim!C:C)} -> South | M17: PROD36 | N17: {=XLOOKUP(M17,Product_Dim!A:A,Product_Dim!C:C)} -> Clothing | O17: {=XLOOKUP(M17,Product_Dim!A:A,Product_Dim!D:D)} -> Tops | P17: Smith-Mills | Q17: STORE9 | R17: {=XLOOKUP(Q17,Store_Dim!A:A,Store_Dim!B:B)} -> Moore, Padilla and Butler | S17: {=XLOOKUP(Q17,Store_Dim!A:A,Store_Dim!E:E)} -> Flagship | T17: =Y17/(U17*(1-V17)) -> 3 | U17: 871.34 | V17: 0.04 | W17: 154 | X17: COD | Y17: 2509.4592 | Z17: {=XLOOKUP(M17,Product_Dim!A:A,Product_Dim!B:B)} -> Women's Summer Dress
A18: SALE16 | B18: 45913 | C18: September | D18: =YEAR(B18) -> 2025 | E18: CUST1276 | F18: 38 | G18: =IF(F18<18,"Under 18", IF(F18<=25,"18-25", IF(F18<=35,"26-35", IF(F18<=45,"36-45", IF(F18<=55,"46-55", IF(F18<=65,"56-65","65+")))))) -> 36-45 | H18: {=XLOOKUP(E18,Customer_Dim!A:A,Customer_Dim!D:D)} -> Male | I18: {=XLOOKUP(E18,Customer_Dim!A:A,Customer_Dim!H:H)} -> Gold | J18: {=XLOOKUP(E18,Customer_Dim!A:A,Customer_Dim!E:E)} -> Ericshire | K18: {=XLOOKUP(E18,Customer_Dim!A:A,Customer_Dim!F:F)} -> Nevada | L18: {=XLOOKUP(Q18,Store_Dim!A:A,Store_Dim!C:C)} -> East | M18: PROD65 | N18: {=XLOOKUP(M18,Product_Dim!A:A,Product_Dim!C:C)} -> Sports | O18: {=XLOOKUP(M18,Product_Dim!A:A,Product_Dim!D:D)} -> Fitness | P18: Montgomery, Benton and Miller | Q18: STORE19 | R18: {=XLOOKUP(Q18,Store_Dim!A:A,Store_Dim!B:B)} -> Mann-Austin | S18: {=XLOOKUP(Q18,Store_Dim!A:A,Store_Dim!E:E)} -> Online | T18: 2 | U18: 451.98 | V18: 0.25 | W18: 423 | X18: Credit Card | Y18: 677.97 | Z18: {=XLOOKUP(M18,Product_Dim!A:A,Product_Dim!B:B)} -> Adjustable Dumbbells 20kg
A19: SALE17 | B19: 45637 | C19: December | D19: =YEAR(B19) -> 2024 | E19: CUST1079 | F19: 22 | G19: =IF(F19<18,"Under 18", IF(F19<=25,"18-25", IF(F19<=35,"26-35", IF(F19<=45,"36-45", IF(F19<=55,"46-55", IF(F19<=65,"56-65","65+")))))) -> 18-25 | H19: {=XLOOKUP(E19,Customer_Dim!A:A,Customer_Dim!D:D)} -> Female | I19: {=XLOOKUP(E19,Customer_Dim!A:A,Customer_Dim!H:H)} -> Platinum | J19: {=XLOOKUP(E19,Customer_Dim!A:A,Customer_Dim!E:E)} -> Nicoleborough | K19: {=XLOOKUP(E19,Customer_Dim!A:A,Customer_Dim!F:F)} -> Arkansas | L19: {=XLOOKUP(Q19,Store_Dim!A:A,Store_Dim!C:C)} -> South | M19: PROD27 | N19: {=XLOOKUP(M19,Product_Dim!A:A,Product_Dim!C:C)} -> Home | O19: {=XLOOKUP(M19,Product_Dim!A:A,Product_Dim!D:D)} -> Decor | P19: Khan, Jones and Paul | Q19: STORE4 | R19: {=XLOOKUP(Q19,Store_Dim!A:A,Store_Dim!B:B)} -> Alexander Group | S19: {=XLOOKUP(Q19,Store_Dim!A:A,Store_Dim!E:E)} -> Online | T19: 2 | U19: 502.69 | V19: 0.23 | W19: 378 | X19: Credit Card | Y19: 774.1426 | Z19: {=XLOOKUP(M19,Product_Dim!A:A,Product_Dim!B:B)} -> Decorative Floor Vase
A20: SALE18 | B20: 45517 | C20: August | D20: =YEAR(B20) -> 2024 | E20: CUST1094 | F20: 43 | G20: =IF(F20<18,"Under 18", IF(F20<=25,"18-25", IF(F20<=35,"26-35", IF(F20<=45,"36-45", IF(F20<=55,"46-55", IF(F20<=65,"56-65","65+")))))) -> 36-45 | H20: {=XLOOKUP(E20,Customer_Dim!A:A,Customer_Dim!D:D)} -> Female | I20: {=XLOOKUP(E20,Customer_Dim!A:A,Customer_Dim!H:H)} -> Gold | J20: {=XLOOKUP(E20,Customer_Dim!A:A,Customer_Dim!E:E)} -> New Amyport | K20: {=XLOOKUP(E20,Customer_Dim!A:A,Customer_Dim!F:F)} -> Nevada | L20: {=XLOOKUP(Q20,Store_Dim!A:A,Store_Dim!C:C)} -> South | M20: PROD39 | N20: {=XLOOKUP(M20,Product_Dim!A:A,Product_Dim!C:C)} -> Electronics | O20: {=XLOOKUP(M20,Product_Dim!A:A,Product_Dim!D:D)} -> Mobile | P20: Cummings and Sons | Q20: STORE4 | R20: {=XLOOKUP(Q20,Store_Dim!A:A,Store_Dim!B:B)} -> Alexander Group | S20: {=XLOOKUP(Q20,Store_Dim!A:A,Store_Dim!E:E)} -> Online | T20: 2 | U20: 559.23 | V20: 0.25 | W20: 301 | X20: COD | Y20: 838.845 | Z20: {=XLOOKUP(M20,Product_Dim!A:A,Product_Dim!B:B)} -> Portable Power Bank
A21: SALE19 | B21: 45369 | C21: March | D21: =YEAR(B21) -> 2024 | E21: CUST1239 | F21: 58 | G21: =IF(F21<18,"Under 18", IF(F21<=25,"18-25", IF(F21<=35,"26-35", IF(F21<=45,"36-45", IF(F21<=55,"46-55", IF(F21<=65,"56-65","65+")))))) -> 56-65 | H21: {=XLOOKUP(E21,Customer_Dim!A:A,Customer_Dim!D:D)} -> Female | I21: {=XLOOKUP(E21,Customer_Dim!A:A,Customer_Dim!H:H)} -> Platinum | J21: {=XLOOKUP(E21,Customer_Dim!A:A,Customer_Dim!E:E)} -> Zamoraborough | K21: {=XLOOKUP(E21,Customer_Dim!A:A,Customer_Dim!F:F)} -> Nevada | L21: {=XLOOKUP(Q21,Store_Dim!A:A,Store_Dim!C:C)} -> East | M21: PROD60 | N21: {=XLOOKUP(M21,Product_Dim!A:A,Product_Dim!C:C)} -> Beauty | O21: {=XLOOKUP(M21,Product_Dim!A:A,Product_Dim!D:D)} -> Fragrance | P21: Gibson, Green and Lopez | Q21: STORE13 | R21: {=XLOOKUP(Q21,Store_Dim!A:A,Store_Dim!B:B)} -> Gardner, Humphrey and Contreras | S21: {=XLOOKUP(Q21,Store_Dim!A:A,Store_Dim!E:E)} -> Flagship | T21: 4 | U21: =Y21/(1-V21)/T21 -> 464.18 | V21: 0.04 | W21: 444 | X21: COD | Y21: 1782.4512 | Z21: {=XLOOKUP(M21,Product_Dim!A:A,Product_Dim!B:B)} -> Luxury Perfume Spray
A22: SALE20 | B22: 45843 | C22: July | D22: =YEAR(B22) -> 2025 | E22: CUST1144 | F22: 62 | G22: =IF(F22<18,"Under 18", IF(F22<=25,"18-25", IF(F22<=35,"26-35", IF(F22<=45,"36-45", IF(F22<=55,"46-55", IF(F22<=65,"56-65","65+")))))) -> 56-65 | H22: {=XLOOKUP(E22,Customer_Dim!A:A,Customer_Dim!D:D)} -> Female | I22: {=XLOOKUP(E22,Customer_Dim!A:A,Customer_Dim!H:H)} -> Bronze | J22: {=XLOOKUP(E22,Customer_Dim!A:A,Customer_Dim!E:E)} -> North Anthonychester | K22: {=XLOOKUP(E22,Customer_Dim!A:A,Customer_Dim!F:F)} -> Nevada | L22: {=XLOOKUP(Q22,Store_Dim!A:A,Store_Dim!C:C)} -> North | M22: PROD72 | N22: {=XLOOKUP(M22,Product_Dim!A:A,Product_Dim!C:C)} -> Sports | O22: {=XLOOKUP(M22,Product_Dim!A:A,Product_Dim!D:D)} -> Fitness | P22: Davis PLC | Q22: STORE17 | R22: {=XLOOKUP(Q22,Store_Dim!A:A,Store_Dim!B:B)} -> Holloway Ltd | S22: {=XLOOKUP(Q22,Store_Dim!A:A,Store_Dim!E:E)} -> Flagship | T22: 3 | U22: 986.04 | V22: 0.27 | W22: 300 | X22: COD | Y22: 2159.4276 | Z22: {=XLOOKUP(M22,Product_Dim!A:A,Product_Dim!B:B)} -> Professional Jump Rope
A23: SALE21 | B23: 45447 | C23: June | D23: =YEAR(B23) -> 2024 | E23: CUST1396 | F23: 25 | G23: =IF(F23<18,"Under 18", IF(F23<=25,"18-25", IF(F23<=35,"26-35", IF(F23<=45,"36-45", IF(F23<=55,"46-55", IF(F23<=65,"56-65","65+")))))) -> 18-25 | H23: {=XLOOKUP(E23,Customer_Dim!A:A,Customer_Dim!D:D)} -> Female | I23: {=XLOOKUP(E23,Customer_Dim!A:A,Customer_Dim!H:H)} -> Silver | J23: {=XLOOKUP(E23,Customer_Dim!A:A,Customer_Dim!E:E)} -> Parkerview | K23: {=XLOOKUP(E23,Customer_Dim!A:A,Customer_Dim!F:F)} -> New York | L23: {=XLOOKUP(Q23,Store_Dim!A:A,Store_Dim!C:C)} -> East | M23: PROD43 | N23: {=XLOOKUP(M23,Product_Dim!A:A,Product_Dim!C:C)} -> Electronics | O23: {=XLOOKUP(M23,Product_Dim!A:A,Product_Dim!D:D)} -> Computer | P23: Robinson Inc | Q23: STORE18 | R23: {=XLOOKUP(Q23,Store_Dim!A:A,Store_Dim!B:B)} -> Guerrero-Schmitt | S23: {=XLOOKUP(Q23,Store_Dim!A:A,Store_Dim!E:E)} -> Flagship | T23: 1 | U23: 589.56 | V23: 0.22 | W23: 266 | X23: Credit Card | Y23: 459.8568 | Z23: {=XLOOKUP(M23,Product_Dim!A:A,Product_Dim!B:B)} -> USB External Hard Drive
A24: SALE22 | B24: 45394 | C24: April | D24: =YEAR(B24) -> 2024 | E24: CUST1476 | F24: 33 | G24: =IF(F24<18,"Under 18", IF(F24<=25,"18-25", IF(F24<=35,"26-35", IF(F24<=45,"36-45", IF(F24<=55,"46-55", IF(F24<=65,"56-65","65+")))))) -> 26-35 | H24: {=XLOOKUP(E24,Customer_Dim!A:A,Customer_Dim!D:D)} -> Female | I24: {=XLOOKUP(E24,Customer_Dim!A:A,Customer_Dim!H:H)} -> Gold | J24: {=XLOOKUP(E24,Customer_Dim!A:A,Customer_Dim!E:E)} -> Anthonymouth | K24: {=XLOOKUP(E24,Customer_Dim!A:A,Customer_Dim!F:F)} -> Oklahoma | L24: {=XLOOKUP(Q24,Store_Dim!A:A,Store_Dim!C:C)} -> East | M24: PROD69 | N24: {=XLOOKUP(M24,Product_Dim!A:A,Product_Dim!C:C)} -> Clothing | O24: {=XLOOKUP(M24,Product_Dim!A:A,Product_Dim!D:D)} -> Bottoms | P24: Fitzpatrick Ltd | Q24: STORE10 | R24: {=XLOOKUP(Q24,Store_Dim!A:A,Store_Dim!B:B)} -> Hill, Wagner and Ballard | S24: {=XLOOKUP(Q24,Store_Dim!A:A,Store_Dim!E:E)} -> Online | T24: 3 | U24: 979.42 | V24: 0.03 | W24: 224 | X24: PayPal | Y24: 2850.1122 | Z24: {=XLOOKUP(M24,Product_Dim!A:A,Product_Dim!B:B)} -> Men's Sports Shorts
A25: SALE23 | B25: 45466 | C25: June | D25: =YEAR(B25) -> 2024 | E25: CUST1368 | F25: 34 | G25: =IF(F25<18,"Under 18", IF(F25<=25,"18-25", IF(F25<=35,"26-35", IF(F25<=45,"36-45", IF(F25<=55,"46-55", IF(F25<=65,"56-65","65+")))))) -> 26-35 | H25: {=XLOOKUP(E25,Customer_Dim!A:A,Customer_Dim!D:D)} -> Female | I25: {=XLOOKUP(E25,Customer_Dim!A:A,Customer_Dim!H:H)} -> Platinum | J25: {=XLOOKUP(E25,Customer_Dim!A:A,Customer_Dim!E:E)} -> West Mathew | K25: {=XLOOKUP(E25,Customer_Dim!A:A,Customer_Dim!F:F)} -> New York | L25: {=XLOOKUP(Q25,Store_Dim!A:A,Store_Dim!C:C)} -> West | M25: PROD12 | N25: {=XLOOKUP(M25,Product_Dim!A:A,Product_Dim!C:C)} -> Beauty | O25: {=XLOOKUP(M25,Product_Dim!A:A,Product_Dim!D:D)} -> Haircare | P25: Rice LLC | Q25: STORE8 | R25: {=XLOOKUP(Q25,Store_Dim!A:A,Store_Dim!B:B)} -> Bean, Jones and Park | S25: {=XLOOKUP(Q25,Store_Dim!A:A,Store_Dim!E:E)} -> Online | T25: 1 | U25: 719.28 | V25: 0.08 | W25: 460 | X25: Credit Card | Y25: 661.7376 | Z25: {=XLOOKUP(M25,Product_Dim!A:A,Product_Dim!B:B)} -> Hair Strengthening Shampoo
A26: SALE24 | B26: 45908 | C26: September | D26: =YEAR(B26) -> 2025 | E26: CUST1186 | F26: 53 | G26: =IF(F26<18,"Under 18", IF(F26<=25,"18-25", IF(F26<=35,"26-35", IF(F26<=45,"36-45", IF(F26<=55,"46-55", IF(F26<=65,"56-65","65+")))))) -> 46-55 | H26: {=XLOOKUP(E26,Customer_Dim!A:A,Customer_Dim!D:D)} -> Male | I26: {=XLOOKUP(E26,Customer_Dim!A:A,Customer_Dim!H:H)} -> Silver | J26: {=XLOOKUP(E26,Customer_Dim!A:A,Customer_Dim!E:E)} -> East Justin | K26: {=XLOOKUP(E26,Customer_Dim!A:A,Customer_Dim!F:F)} -> Missouri | L26: {=XLOOKUP(Q26,Store_Dim!A:A,Store_Dim!C:C)} -> East | M26: PROD67 | N26: {=XLOOKUP(M26,Product_Dim!A:A,Product_Dim!C:C)} -> Electronics | O26: {=XLOOKUP(M26,Product_Dim!A:A,Product_Dim!D:D)} -> Accessories | P26: Flores-Davis | Q26: STORE6 | R26: {=XLOOKUP(Q26,Store_Dim!A:A,Store_Dim!B:B)} -> Benson-Elliott | S26: {=XLOOKUP(Q26,Store_Dim!A:A,Store_Dim!E:E)} -> Online | T26: 3 | U26: 77.6 | V26: 0.07 | W26: 476 | X26: Credit Card | Y26: 216.504 | Z26: {=XLOOKUP(M26,Product_Dim!A:A,Product_Dim!B:B)} -> Smart LED Light Strip
A27: SALE25 | B27: 45552 | C27: September | D27: =YEAR(B27) -> 2024 | E27: CUST1381 | F27: 50 | G27: =IF(F27<18,"Under 18", IF(F27<=25,"18-25", IF(F27<=35,"26-35", IF(F27<=45,"36-45", IF(F27<=55,"46-55", IF(F27<=65,"56-65","65+")))))) -> 46-55 | H27: {=XLOOKUP(E27,Customer_Dim!A:A,Customer_Dim!D:D)} -> Male | I27: {=XLOOKUP(E27,Customer_Dim!A:A,Customer_Dim!H:H)} -> Silver | J27: {=XLOOKUP(E27,Customer_Dim!A:A,Customer_Dim!E:E)} -> Andrewsland | K27: {=XLOOKUP(E27,Customer_Dim!A:A,Customer_Dim!F:F)} -> Alabama | L27: {=XLOOKUP(Q27,Store_Dim!A:A,Store_Dim!C:C)} -> North | M27: PROD5 | N27: {=XLOOKUP(M27,Product_Dim!A:A,Product_Dim!C:C)} -> Clothing | O27: {=XLOOKUP(M27,Product_Dim!A:A,Product_Dim!D:D)} -> Accessories | P27: Baldwin, Garza and Gonzalez | Q27: STORE3 | R27: {=XLOOKUP(Q27,Store_Dim!A:A,Store_Dim!B:B)} -> Johnson-Wright | S27: {=XLOOKUP(Q27,Store_Dim!A:A,Store_Dim!E:E)} -> Outlet | T27: 4 | U27: 852.71 | V27: 0.14 | W27: 59 | X27: PayPal | Y27: 2933.3224 | Z27: {=XLOOKUP(M27,Product_Dim!A:A,Product_Dim!B:B)} -> Men's Leather Belt
A28: SALE26 | B28: 45294 | C28: January | D28: =YEAR(B28) -> 2024 | E28: CUST1213 | F28: 42 | G28: =IF(F28<18,"Under 18", IF(F28<=25,"18-25", IF(F28<=35,"26-35", IF(F28<=45,"36-45", IF(F28<=55,"46-55", IF(F28<=65,"56-65","65+")))))) -> 36-45 | H28: {=XLOOKUP(E28,Customer_Dim!A:A,Customer_Dim!D:D)} -> Female | I28: {=XLOOKUP(E28,Customer_Dim!A:A,Customer_Dim!H:H)} -> Platinum | J28: {=XLOOKUP(E28,Customer_Dim!A:A,Customer_Dim!E:E)} -> West Markport | K28: {=XLOOKUP(E28,Customer_Dim!A:A,Customer_Dim!F:F)} -> North Dakota | L28: {=XLOOKUP(Q28,Store_Dim!A:A,Store_Dim!C:C)} -> West | M28: PROD98 | N28: {=XLOOKUP(M28,Product_Dim!A:A,Product_Dim!C:C)} -> Electronics | O28: {=XLOOKUP(M28,Product_Dim!A:A,Product_Dim!D:D)} -> Audio | P28: Flores-King | Q28: STORE8 | R28: {=XLOOKUP(Q28,Store_Dim!A:A,Store_Dim!B:B)} -> Bean, Jones and Park | S28: {=XLOOKUP(Q28,Store_Dim!A:A,Store_Dim!E:E)} -> Online | T28: 4 | U28: 156.16 | V28: =1-Y28/(U28*T28) -> 0.04 | W28: 73 | X28: Credit Card | Y28: 599.6544 | Z28: {=XLOOKUP(M28,Product_Dim!A:A,Product_Dim!B:B)} -> Portable Bluetooth Speaker
A29: SALE27 | B29: 45710 | C29: February | D29: =YEAR(B29) -> 2025 | E29: CUST1200 | F29: 30 | G29: =IF(F29<18,"Under 18", IF(F29<=25,"18-25", IF(F29<=35,"26-35", IF(F29<=45,"36-45", IF(F29<=55,"46-55", IF(F29<=65,"56-65","65+")))))) -> 26-35 | H29: {=XLOOKUP(E29,Customer_Dim!A:A,Customer_Dim!D:D)} -> Male | I29: {=XLOOKUP(E29,Customer_Dim!A:A,Customer_Dim!H:H)} -> Platinum | J29: {=XLOOKUP(E29,Customer_Dim!A:A,Customer_Dim!E:E)} -> South Jerry | K29: {=XLOOKUP(E29,Customer_Dim!A:A,Customer_Dim!F:F)} -> Maine | L29: {=XLOOKUP(Q29,Store_Dim!A:A,Store_Dim!C:C)} -> West | M29: PROD77 | N29: {=XLOOKUP(M29,Product_Dim!A:A,Product_Dim!C:C)} -> Electronics | O29: {=XLOOKUP(M29,Product_Dim!A:A,Product_Dim!D:D)} -> Appliances | P29: White, Reeves and Woods | Q29: STORE8 | R29: {=XLOOKUP(Q29,Store_Dim!A:A,Store_Dim!B:B)} -> Bean, Jones and Park | S29: {=XLOOKUP(Q29,Store_Dim!A:A,Store_Dim!E:E)} -> Online | T29: 3 | U29: 815.49 | V29: 0.17 | W29: 104 | X29: Credit Card | Y29: 2030.5701 | Z29: {=XLOOKUP(M29,Product_Dim!A:A,Product_Dim!B:B)} -> WiFi Mesh Router
A30: SALE28 | B30: 45923 | C30: September | D30: =YEAR(B30) -> 2025 | E30: CUST1148 | F30: 42 | G30: =IF(F30<18,"Under 18", IF(F30<=25,"18-25", IF(F30<=35,"26-35", IF(F30<=45,"36-45", IF(F30<=55,"46-55", IF(F30<=65,"56-65","65+")))))) -> 36-45 | H30: {=XLOOKUP(E30,Customer_Dim!A:A,Customer_Dim!D:D)} -> Female | I30: {=XLOOKUP(E30,Customer_Dim!A:A,Customer_Dim!H:H)} -> Bronze | J30: {=XLOOKUP(E30,Customer_Dim!A:A,Customer_Dim!E:E)} -> New Brian | K30: {=XLOOKUP(E30,Customer_Dim!A:A,Customer_Dim!F:F)} -> Wisconsin | L30: {=XLOOKUP(Q30,Store_Dim!A:A,Store_Dim!C:C)} -> South | M30: PROD13 | N30: {=XLOOKUP(M30,Product_Dim!A:A,Product_Dim!C:C)} -> Electronics | O30: {=XLOOKUP(M30,Product_Dim!A:A,Product_Dim!D:D)} -> Accessories | P30: Dawson-Perkins | Q30: STORE2 | R30: {=XLOOKUP(Q30,Store_Dim!A:A,Store_Dim!B:B)} -> Black-Horn | S30: {=XLOOKUP(Q30,Store_Dim!A:A,Store_Dim!E:E)} -> Outlet | T30: 2 | U30: 74.21 | V30: 0.11 | W30: 453 | X30: PayPal | Y30: 132.0938 | Z30: {=XLOOKUP(M30,Product_Dim!A:A,Product_Dim!B:B)} -> USB-C Fast Charger
A31: SALE29 | B31: 45302 | C31: January | D31: =YEAR(B31) -> 2024 | E31: CUST1348 | F31: 55 | G31: =IF(F31<18,"Under 18", IF(F31<=25,"18-25", IF(F31<=35,"26-35", IF(F31<=45,"36-45", IF(F31<=55,"46-55", IF(F31<=65,"56-65","65+")))))) -> 46-55 | H31: {=XLOOKUP(E31,Customer_Dim!A:A,Customer_Dim!D:D)} -> Male | I31: {=XLOOKUP(E31,Customer_Dim!A:A,Customer_Dim!H:H)} -> Silver | J31: {=XLOOKUP(E31,Customer_Dim!A:A,Customer_Dim!E:E)} -> Shannonview | K31: {=XLOOKUP(E31,Customer_Dim!A:A,Customer_Dim!F:F)} -> Pennsylvania | L31: {=XLOOKUP(Q31,Store_Dim!A:A,Store_Dim!C:C)} -> North | M31: PROD99 | N31: {=XLOOKUP(M31,Product_Dim!A:A,Product_Dim!C:C)} -> Home | O31: {=XLOOKUP(M31,Product_Dim!A:A,Product_Dim!D:D)} -> Kitchen | P31: Campbell Ltd | Q31: STORE3 | R31: {=XLOOKUP(Q31,Store_Dim!A:A,Store_Dim!B:B)} -> Johnson-Wright | S31: {=XLOOKUP(Q31,Store_Dim!A:A,Store_Dim!E:E)} -> Outlet | T31: =Y31/(U31*(1-V31)) -> 4 | U31: 451.67 | V31: 0.15 | W31: 146 | X31: Credit Card | Y31: 1535.678 | Z31: {=XLOOKUP(M31,Product_Dim!A:A,Product_Dim!B:B)} -> Stainless Steel Cookware Set
A32: SALE30 | B32: 45217 | C32: October | D32: =YEAR(B32) -> 2023 | E32: CUST1028 | F32: 27 | G32: =IF(F32<18,"Under 18", IF(F32<=25,"18-25", IF(F32<=35,"26-35", IF(F32<=45,"36-45", IF(F32<=55,"46-55", IF(F32<=65,"56-65","65+")))))) -> 26-35 | H32: {=XLOOKUP(E32,Customer_Dim!A:A,Customer_Dim!D:D)} -> Female | I32: {=XLOOKUP(E32,Customer_Dim!A:A,Customer_Dim!H:H)} -> Platinum | J32: {=XLOOKUP(E32,Customer_Dim!A:A,Customer_Dim!E:E)} -> New David | K32: {=XLOOKUP(E32,Customer_Dim!A:A,Customer_Dim!F:F)} -> New Jersey | L32: {=XLOOKUP(Q32,Store_Dim!A:A,Store_Dim!C:C)} -> East | M32: PROD5 | N32: {=XLOOKUP(M32,Product_Dim!A:A,Product_Dim!C:C)} -> Clothing | O32: {=XLOOKUP(M32,Product_Dim!A:A,Product_Dim!D:D)} -> Accessories | P32: Baldwin, Garza and Gonzalez | Q32: STORE19 | R32: {=XLOOKUP(Q32,Store_Dim!A:A,Store_Dim!B:B)} -> Mann-Austin | S32: {=XLOOKUP(Q32,Store_Dim!A:A,Store_Dim!E:E)} -> Online | T32: 1 | U32: 429.38 | V32: 0.13 | W32: 59 | X32: PayPal | Y32: 373.5606 | Z32: {=XLOOKUP(M32,Product_Dim!A:A,Product_Dim!B:B)} -> Men's Leather Belt
A33: SALE31 | B33: 45593 | C33: October | D33: =YEAR(B33) -> 2024 | E33: CUST1412 | F33: 23 | G33: =IF(F33<18,"Under 18", IF(F33<=25,"18-25", IF(F33<=35,"26-35", IF(F33<=45,"36-45", IF(F33<=55,"46-55", IF(F33<=65,"56-65","65+")))))) -> 18-25 | H33: {=XLOOKUP(E33,Customer_Dim!A:A,Customer_Dim!D:D)} -> Female | I33: {=XLOOKUP(E33,Customer_Dim!A:A,Customer_Dim!H:H)} -> Gold | J33: {=XLOOKUP(E33,Customer_Dim!A:A,Customer_Dim!E:E)} -> East Andrea | K33: {=XLOOKUP(E33,Customer_Dim!A:A,Customer_Dim!F:F)} -> Michigan | L33: {=XLOOKUP(Q33,Store_Dim!A:A,Store_Dim!C:C)} -> North | M33: PROD53 | N33: {=XLOOKUP(M33,Product_Dim!A:A,Product_Dim!C:C)} -> Clothing | O33: {=XLOOKUP(M33,Product_Dim!A:A,Product_Dim!D:D)} -> Bottoms | P33: Hamilton, Woods and Walker | Q33: STORE12 | R33: {=XLOOKUP(Q33,Store_Dim!A:A,Store_Dim!B:B)} -> Thomas, Bridges and Harris | S33: {=XLOOKUP(Q33,Store_Dim!A:A,Store_Dim!E:E)} -> Online | T33: 2 | U33: 148.96 | V33: 0.03 | W33: 125 | X33: COD | Y33: 288.9824 | Z33: {=XLOOKUP(M33,Product_Dim!A:A,Product_Dim!B:B)} -> Men's Track Pants
A34: SALE32 | B34: 45597 | C34: November | D34: =YEAR(B34) -> 2024 | E34: CUST1398 | F34: 54 | G34: =IF(F34<18,"Under 18", IF(F34<=25,"18-25", IF(F34<=35,"26-35", IF(F34<=45,"36-45", IF(F34<=55,"46-55", IF(F34<=65,"56-65","65+")))))) -> 46-55 | H34: {=XLOOKUP(E34,Customer_Dim!A:A,Customer_Dim!D:D)} -> Male | I34: {=XLOOKUP(E34,Customer_Dim!A:A,Customer_Dim!H:H)} -> Bronze | J34: {=XLOOKUP(E34,Customer_Dim!A:A,Customer_Dim!E:E)} -> Cheyenneborough | K34: {=XLOOKUP(E34,Customer_Dim!A:A,Customer_Dim!F:F)} -> New Hampshire | L34: {=XLOOKUP(Q34,Store_Dim!A:A,Store_Dim!C:C)} -> West | M34: PROD75 | N34: {=XLOOKUP(M34,Product_Dim!A:A,Product_Dim!C:C)} -> Clothing | O34: {=XLOOKUP(M34,Product_Dim!A:A,Product_Dim!D:D)} -> Footwear | P34: Poole PLC | Q34: STORE8 | R34: {=XLOOKUP(Q34,Store_Dim!A:A,Store_Dim!B:B)} -> Bean, Jones and Park | S34: {=XLOOKUP(Q34,Store_Dim!A:A,Store_Dim!E:E)} -> Online | T34: 4 | U34: 313.83 | V34: 0.08 | W34: 82 | X34: Credit Card | Y34: 1154.8944 | Z34: {=XLOOKUP(M34,Product_Dim!A:A,Product_Dim!B:B)} -> Women's Ankle Boots
A35: SALE33 | B35: 45620 | C35: November | D35: =YEAR(B35) -> 2024 | E35: CUST1453 | F35: 62 | G35: =IF(F35<18,"Under 18", IF(F35<=25,"18-25", IF(F35<=35,"26-35", IF(F35<=45,"36-45", IF(F35<=55,"46-55", IF(F35<=65,"56-65","65+")))))) -> 56-65 | H35: {=XLOOKUP(E35,Customer_Dim!A:A,Customer_Dim!D:D)} -> Female | I35: {=XLOOKUP(E35,Customer_Dim!A:A,Customer_Dim!H:H)} -> Platinum | J35: {=XLOOKUP(E35,Customer_Dim!A:A,Customer_Dim!E:E)} -> Lake Carolyn | K35: {=XLOOKUP(E35,Customer_Dim!A:A,Customer_Dim!F:F)} -> Hawaii | L35: {=XLOOKUP(Q35,Store_Dim!A:A,Store_Dim!C:C)} -> East | M35: PROD12 | N35: {=XLOOKUP(M35,Product_Dim!A:A,Product_Dim!C:C)} -> Beauty | O35: {=XLOOKUP(M35,Product_Dim!A:A,Product_Dim!D:D)} -> Haircare | P35: Rice LLC | Q35: STORE6 | R35: {=XLOOKUP(Q35,Store_Dim!A:A,Store_Dim!B:B)} -> Benson-Elliott | S35: {=XLOOKUP(Q35,Store_Dim!A:A,Store_Dim!E:E)} -> Online | T35: 2 | U35: 717.31 | V35: 0.15 | W35: 460 | X35: Credit Card | Y35: 1219.427 | Z35: {=XLOOKUP(M35,Product_Dim!A:A,Product_Dim!B:B)} -> Hair Strengthening Shampoo
A36: SALE34 | B36: 45215 | C36: October | D36: =YEAR(B36) -> 2023 | E36: CUST1344 | F36: 39 | G36: =IF(F36<18,"Under 18", IF(F36<=25,"18-25", IF(F36<=35,"26-35", IF(F36<=45,"36-45", IF(F36<=55,"46-55", IF(F36<=65,"56-65","65+")))))) -> 36-45 | H36: {=XLOOKUP(E36,Customer_Dim!A:A,Customer_Dim!D:D)} -> Male | I36: {=XLOOKUP(E36,Customer_Dim!A:A,Customer_Dim!H:H)} -> Gold | J36: {=XLOOKUP(E36,Customer_Dim!A:A,Customer_Dim!E:E)} -> West Victoriaborough | K36: {=XLOOKUP(E36,Customer_Dim!A:A,Customer_Dim!F:F)} -> New Mexico | L36: {=XLOOKUP(Q36,Store_Dim!A:A,Store_Dim!C:C)} -> North | M36: PROD79 | N36: {=XLOOKUP(M36,Product_Dim!A:A,Product_Dim!C:C)} -> Home | O36: {=XLOOKUP(M36,Product_Dim!A:A,Product_Dim!D:D)} -> Lighting | P36: Ramirez-Hanson | Q36: STORE1 | R36: {=XLOOKUP(Q36,Store_Dim!A:A,Store_Dim!B:B)} -> Martinez, Adkins and Johnson | S36: {=XLOOKUP(Q36,Store_Dim!A:A,Store_Dim!E:E)} -> Flagship | T36: =Y36/(U36*(1-V36)) -> 3 | U36: 873.22 | V36: 0.18 | W36: 469 | X36: Credit Card | Y36: 2148.1212 | Z36: {=XLOOKUP(M36,Product_Dim!A:A,Product_Dim!B:B)} -> Decorative Lamp Shade
A37: SALE35 | B37: 45878 | C37: August | D37: =YEAR(B37) -> 2025 | E37: CUST1218 | F37: 46 | G37: =IF(F37<18,"Under 18", IF(F37<=25,"18-25", IF(F37<=35,"26-35", IF(F37<=45,"36-45", IF(F37<=55,"46-55", IF(F37<=65,"56-65","65+")))))) -> 46-55 | H37: {=XLOOKUP(E37,Customer_Dim!A:A,Customer_Dim!D:D)} -> Male | I37: {=XLOOKUP(E37,Customer_Dim!A:A,Customer_Dim!H:H)} -> Platinum | J37: {=XLOOKUP(E37,Customer_Dim!A:A,Customer_Dim!E:E)} -> Edwardland | K37: {=XLOOKUP(E37,Customer_Dim!A:A,Customer_Dim!F:F)} -> California | L37: {=XLOOKUP(Q37,Store_Dim!A:A,Store_Dim!C:C)} -> North | M37: PROD16 | N37: {=XLOOKUP(M37,Product_Dim!A:A,Product_Dim!C:C)} -> Beauty | O37: {=XLOOKUP(M37,Product_Dim!A:A,Product_Dim!D:D)} -> Grooming | P37: Erickson-Green | Q37: STORE3 | R37: {=XLOOKUP(Q37,Store_Dim!A:A,Store_Dim!B:B)} -> Johnson-Wright | S37: {=XLOOKUP(Q37,Store_Dim!A:A,Store_Dim!E:E)} -> Outlet | T37: 4 | U37: 109.36 | V37: 0.19 | W37: 256 | X37: COD | Y37: 354.3264 | Z37: {=XLOOKUP(M37,Product_Dim!A:A,Product_Dim!B:B)} -> Beard Grooming Kit
A38: SALE36 | B38: 45635 | C38: December | D38: =YEAR(B38) -> 2024 | E38: CUST1086 | F38: 19 | G38: =IF(F38<18,"Under 18", IF(F38<=25,"18-25", IF(F38<=35,"26-35", IF(F38<=45,"36-45", IF(F38<=55,"46-55", IF(F38<=65,"56-65","65+")))))) -> 18-25 | H38: {=XLOOKUP(E38,Customer_Dim!A:A,Customer_Dim!D:D)} -> Female | I38: {=XLOOKUP(E38,Customer_Dim!A:A,Customer_Dim!H:H)} -> Gold | J38: {=XLOOKUP(E38,Customer_Dim!A:A,Customer_Dim!E:E)} -> Austinfurt | K38: {=XLOOKUP(E38,Customer_Dim!A:A,Customer_Dim!F:F)} -> Mississippi | L38: {=XLOOKUP(Q38,Store_Dim!A:A,Store_Dim!C:C)} -> South | M38: PROD5 | N38: {=XLOOKUP(M38,Product_Dim!A:A,Product_Dim!C:C)} -> Clothing | O38: {=XLOOKUP(M38,Product_Dim!A:A,Product_Dim!D:D)} -> Accessories | P38: Baldwin, Garza and Gonzalez | Q38: STORE7 | R38: {=XLOOKUP(Q38,Store_Dim!A:A,Store_Dim!B:B)} -> Martinez-Mullins | S38: {=XLOOKUP(Q38,Store_Dim!A:A,Store_Dim!E:E)} -> Online | T38: 3 | U38: 559.52 | V38: 0.16 | W38: 59 | X38: PayPal | Y38: 1409.9904 | Z38: {=XLOOKUP(M38,Product_Dim!A:A,Product_Dim!B:B)} -> Men's Leather Belt
A39: SALE37 | B39: 45329 | C39: February | D39: =YEAR(B39) -> 2024 | E39: CUST1492 | F39: 59 | G39: =IF(F39<18,"Under 18", IF(F39<=25,"18-25", IF(F39<=35,"26-35", IF(F39<=45,"36-45", IF(F39<=55,"46-55", IF(F39<=65,"56-65","65+")))))) -> 56-65 | H39: {=XLOOKUP(E39,Customer_Dim!A:A,Customer_Dim!D:D)} -> Female | I39: {=XLOOKUP(E39,Customer_Dim!A:A,Customer_Dim!H:H)} -> Platinum | J39: {=XLOOKUP(E39,Customer_Dim!A:A,Customer_Dim!E:E)} -> Port Carol | K39: {=XLOOKUP(E39,Customer_Dim!A:A,Customer_Dim!F:F)} -> Florida | L39: {=XLOOKUP(Q39,Store_Dim!A:A,Store_Dim!C:C)} -> North | M39: PROD10 | N39: {=XLOOKUP(M39,Product_Dim!A:A,Product_Dim!C:C)} -> Home | O39: {=XLOOKUP(M39,Product_Dim!A:A,Product_Dim!D:D)} -> Kitchen | P39: Hamilton Group | Q39: STORE17 | R39: {=XLOOKUP(Q39,Store_Dim!A:A,Store_Dim!B:B)} -> Holloway Ltd | S39: {=XLOOKUP(Q39,Store_Dim!A:A,Store_Dim!E:E)} -> Flagship | T39: 3 | U39: 121.76 | V39: 0.27 | W39: 308 | X39: PayPal | Y39: 266.6544 | Z39: {=XLOOKUP(M39,Product_Dim!A:A,Product_Dim!B:B)} -> Ceramic Kitchen Bowl Set
